
# Created by Ruins mod version 14.6 Ingame Parser
# authoring Player: LiquidDestiny

weight=1
embed_into_distance=3
acceptable_target_blocks=
unacceptable_target_blocks=flowing_water,water,flowing_lava,lava
dimensions=10,13,13
allowable_overhang=0
max_leveling=2
leveling_buffer=0
preserve_water=0
preserve_lava=0

rule1=0,100,ExtrabiomesXL:terrain_blocks2-0
rule2=0,100,Thaumcraft:blockCosmeticSolid-1
rule3=0,100,minecraft:obsidian-0
rule4=0,100,minecraft:lava-0
rule5=0,100,minecraft:lava-10
rule6=0,100,minecraft:lava-2
rule7=0,100,MobSpawner:PigZombie
rule8=0,100,ExtrabiomesXL:grass-2
rule9=0,100,witchery:circleglyphinfernal-3
rule10=0,100,witchery:circleglyphinfernal-8
rule11=0,100,witchery:circleglyphinfernal-2
rule12=0,100,witchery:circleglyphinfernal-7
rule13=0,100,witchery:circleglyphinfernal-4
rule14=0,100,witchery:circleglyphinfernal-9
rule15=0,100,witchery:circleglyphinfernal-10
rule16=0,100,Thaumcraft:blockCosmeticSolid-0
rule17=0,100,witchery:circleglyphinfernal-6
rule18=0,100,witchery:circleglyphinfernal-5
rule19=0,100,witchery:circleglyphinfernal-11
rule20=0,100,witchery:circleglyphinfernal-1
rule21=0,100,witchery:circleglyphinfernal-0
rule22=0,100,ExtrabiomesXL:grass-4
rule23=0,100,CarpentersBlocks:blockCarpentersLever-1
rule24=0,100,ForgeMultipart:block-0
rule25=0,100,AWWayofTime:blockTeleposer-0
rule26=0,100,minecraft:netherrack-0
rule27=0,100,minecraft:fire-15

layer
1,1,1,1,1,1,1,1,1,1,1,1,1
1,1,1,1,1,1,1,1,1,1,1,1,1
1,1,1,1,1,1,1,1,1,1,1,1,1
1,1,1,1,1,1,1,1,1,1,1,1,1
1,1,1,1,2,3,3,3,2,1,1,1,1
1,1,1,1,3,4,4,4,3,1,1,1,1
1,1,1,1,3,4,4,4,3,1,1,1,1
1,1,1,1,3,4,4,4,3,1,1,1,1
1,1,1,1,2,3,3,3,2,1,1,1,1
1,1,1,1,1,1,1,1,1,1,0,1,1
1,1,1,1,1,1,1,1,1,1,1,1,1
1,1,1,1,1,1,1,1,1,1,1,1,1
1,1,1,1,1,1,1,1,1,1,1,1,1
endlayer

layer
1,1,1,1,1,1,1,1,1,1,1,1,1
1,1,1,1,1,1,1,1,1,1,1,1,1
1,1,1,1,1,1,1,1,1,1,1,1,1
1,1,1,1,1,1,1,1,1,1,1,1,1
1,1,1,1,2,3,3,3,2,1,1,1,1
1,1,1,1,3,4,5,4,3,1,1,1,1
1,1,1,1,3,5,0,5,3,1,1,1,1
1,1,1,1,3,4,5,4,3,1,1,1,1
1,1,1,1,2,3,3,3,2,1,1,1,1
1,1,1,1,1,1,1,1,1,1,1,1,1
1,1,1,1,1,1,1,1,1,1,1,1,1
1,1,1,1,1,1,1,1,1,1,1,1,1
1,1,1,1,1,1,1,1,1,1,1,1,1
endlayer

layer
1,1,1,1,1,1,1,1,1,1,1,1,1
1,1,1,1,2,2,2,2,2,1,1,1,1
1,1,1,2,1,1,2,1,1,2,1,1,1
1,1,2,1,1,1,2,1,1,1,2,1,1
1,2,1,1,2,3,3,3,2,1,1,2,1
1,2,1,1,3,4,6,4,3,1,1,2,1
1,2,2,2,3,6,0,6,3,2,2,2,1
1,2,1,1,3,4,6,4,3,1,1,2,1
1,2,1,1,2,3,3,3,7,1,1,2,1
1,1,2,1,1,1,2,1,1,1,2,1,1
1,1,1,2,1,1,2,1,1,2,1,1,1
1,1,1,1,2,2,2,2,2,1,1,1,1
1,1,1,1,1,1,1,1,1,1,1,1,1
endlayer

layer
0,0,0,8,8,0,8,8,0,0,0,0,0
0,0,0,0,13,12,11,10,9,0,0,0,0
0,0,0,12,0,0,14,8,0,10,0,0,0
8,0,12,0,0,0,15,0,0,0,10,0,0
0,18,0,0,16,17,15,11,16,0,0,13,0
0,15,0,0,17,0,0,0,10,0,0,12,0
0,21,20,20,13,0,0,0,15,9,13,19,0
0,20,0,0,17,0,0,0,20,0,0,11,0
0,18,0,0,16,18,19,21,16,0,0,9,22
0,0,17,0,0,0,10,0,0,0,17,0,0
0,0,0,21,0,0,18,0,0,20,0,22,0
0,0,0,0,13,20,12,11,15,0,0,0,0
0,0,0,0,0,0,0,0,0,0,0,0,0
endlayer

layer
0,0,0,0,0,0,0,0,0,0,0,0,0
0,0,0,0,0,0,0,0,0,0,0,0,0
0,0,0,0,0,0,0,0,0,0,0,0,0
0,0,0,0,0,0,0,0,0,0,0,0,0
0,0,0,0,16,0,0,0,16,0,0,0,0
0,0,0,0,0,0,0,0,0,0,0,0,0
0,0,0,0,0,0,0,0,0,0,0,0,0
0,0,0,0,0,0,0,0,0,0,0,0,0
0,0,0,0,16,0,0,0,16,0,0,0,0
0,0,0,0,0,0,0,0,0,0,0,0,0
0,0,0,0,0,0,0,0,0,0,0,0,0
0,0,0,0,0,0,0,0,0,0,0,0,0
0,0,0,0,0,0,0,0,0,0,0,0,0
endlayer

layer
0,0,0,0,0,0,0,0,0,0,0,0,0
0,0,0,0,0,0,0,0,0,0,0,0,0
0,0,0,0,0,0,0,0,0,0,0,0,0
0,0,0,0,0,0,0,0,0,0,0,0,0
0,0,0,0,2,0,0,0,2,0,0,0,0
0,0,0,0,0,0,0,0,0,0,0,0,0
0,0,0,0,0,0,0,0,0,0,0,0,0
0,0,0,0,0,0,0,0,0,0,0,0,0
0,0,0,0,2,0,0,0,2,0,0,0,0
0,0,0,0,0,0,0,0,0,0,0,0,0
0,0,0,0,0,0,0,0,0,0,0,0,0
0,0,0,0,0,0,0,0,0,0,0,0,0
0,0,0,0,0,0,0,0,0,0,0,0,0
endlayer

layer
0,0,0,0,0,0,0,0,0,0,0,0,0
0,0,0,0,0,0,0,0,0,0,0,0,0
0,0,0,0,0,0,0,0,0,0,0,0,0
0,0,0,0,0,0,0,0,0,0,0,0,0
0,0,0,0,0,2,2,2,0,0,0,0,0
0,0,0,0,2,0,24,0,2,0,0,0,0
0,0,0,0,2,24,25,24,2,0,0,0,0
0,0,0,0,2,0,24,0,2,0,0,0,0
0,0,0,0,0,2,2,2,0,0,0,0,0
0,0,0,0,0,0,0,0,0,0,0,0,0
0,0,0,0,0,0,0,0,0,0,0,0,0
0,0,0,0,0,0,0,0,0,0,0,0,0
0,0,0,0,0,0,0,0,0,0,0,0,0
endlayer

layer
0,0,0,0,0,0,0,0,0,0,0,0,0
0,0,0,0,0,0,0,0,0,0,0,0,0
0,0,0,0,0,0,0,0,0,0,0,0,0
0,0,0,0,0,0,0,0,0,0,0,0,0
0,0,0,0,0,0,2,0,0,0,0,0,0
0,0,0,0,0,0,3,0,0,0,0,0,0
0,0,0,0,2,3,0,3,2,0,0,0,0
0,0,0,0,0,0,3,0,0,0,0,0,0
0,0,0,0,0,0,2,0,0,0,0,0,0
0,0,0,0,0,0,0,0,0,0,0,0,0
0,0,0,0,0,0,0,0,0,0,0,0,0
0,0,0,0,0,0,0,0,0,0,0,0,0
0,0,0,0,0,0,0,0,0,0,0,0,0
endlayer

layer
0,0,0,0,0,0,0,0,0,0,0,0,0
0,0,0,0,0,0,0,0,0,0,0,0,0
0,0,0,0,0,0,0,0,0,0,0,0,0
0,0,0,0,0,0,0,0,0,0,0,0,0
0,0,0,0,0,0,0,0,0,0,0,0,0
0,0,0,0,0,0,2,0,0,0,0,0,0
0,0,0,0,0,2,26,2,0,0,0,0,0
0,0,0,0,0,0,2,0,0,0,0,0,0
0,0,0,0,0,0,0,0,0,0,0,0,0
0,0,0,0,0,0,0,0,0,0,0,0,0
0,0,0,0,0,0,0,0,0,0,0,0,0
0,0,0,0,0,0,0,0,0,0,0,0,0
0,0,0,0,0,0,0,0,0,0,0,0,0
endlayer

layer
0,0,0,0,0,0,0,0,0,0,0,0,0
0,0,0,0,0,0,0,0,0,0,0,0,0
0,0,0,0,0,0,0,0,0,0,0,0,0
0,0,0,0,0,0,0,0,0,0,0,0,0
0,0,0,0,0,0,0,0,0,0,0,0,0
0,0,0,0,0,0,0,0,0,0,0,0,0
0,0,0,0,0,0,27,0,0,0,0,0,0
0,0,0,0,0,0,0,0,0,0,0,0,0
0,0,0,0,0,0,0,0,0,0,0,0,0
0,0,0,0,0,0,0,0,0,0,0,0,0
0,0,0,0,0,0,0,0,0,0,0,0,0
0,0,0,0,0,0,0,0,0,0,0,0,0
0,0,0,0,0,0,0,0,0,0,0,0,0
endlayer

