
# Created by Ruins mod version 14.6 Ingame Parser
# authoring Player: thephoenixlodge

weight=1
embed_into_distance=4
acceptable_target_blocks=
unacceptable_target_blocks=flowing_water,water,flowing_lava,lava
dimensions=11,9,15
allowable_overhang=0
max_leveling=2
leveling_buffer=0
preserve_water=0
preserve_lava=0

rule1=0,100,minecraft:stone-0
rule2=0,100,chisel:grimstone-7
rule3=0,100,chisel:grimstone-12
rule4=0,100,minecraft:web-0
rule5=0,100,IInventory;Thaumcraft:blockStoneDevice;HardcoreQuesting:bags#1#1#0-1
rule6=0,100,GraveStone:GSSpawner-1
rule7=0,100,minecraft:ladder-2
rule8=0,100,ExtrabiomesXL:terrain_blocks2-0
rule9=0,100,chisel:factoryblock-11
rule10=0,100,Railcraft:brick.abyssal-2
rule11=0,100,chisel:grimstone-3
rule12=0,100,GardenContainers:decorative_pot-0
rule13=0,100,GraveStone:GSPileOfBones-1
rule14=0,100,Railcraft:brick.abyssal-5
rule15=0,100,minecraft:nether_brick_fence-0
rule16=0,100,GraveStone:GSPileOfBones-0
rule17=0,100,witchery:coffinblock-10
rule18=0,100,witchery:coffinblock-2
rule19=0,100,Railcraft:brick.abyssal-0
rule20=0,100,GardenCore:small_fire-0
rule21=0,100,minecraft:stone_slab-6
rule22=0,100,minecraft:stone_slab-14
rule23=0,100,minecraft:double_stone_slab-6

layer
1,1,1,1,1,1,1,1,1,1,1,1,1,1,1
1,1,1,1,1,1,1,1,1,1,1,1,1,1,1
1,1,1,1,1,1,1,2,2,2,2,1,1,1,1
1,1,1,1,1,1,2,3,3,3,3,2,1,1,1
1,1,1,1,1,1,2,3,3,3,3,3,2,1,1
1,1,1,1,1,1,2,3,3,3,3,2,1,1,1
1,1,1,1,1,1,1,2,2,2,2,1,1,1,1
1,1,1,1,1,1,1,1,1,1,1,1,1,1,1
1,1,1,1,1,1,1,1,1,1,1,1,1,1,1
endlayer

layer
1,1,1,1,1,1,1,1,1,1,1,1,1,1,1
1,1,1,1,1,1,1,1,1,1,1,1,1,1,1
1,1,1,1,1,1,1,2,2,2,2,1,1,1,1
1,1,1,1,1,1,2,0,0,0,4,2,1,1,1
1,1,1,1,1,1,2,7,0,6,0,5,2,1,1
1,1,1,1,1,1,2,4,0,0,0,2,1,1,1
1,1,1,1,1,1,1,2,2,2,2,1,1,1,1
1,1,1,1,1,1,1,1,1,1,1,1,1,1,1
1,1,1,1,1,1,1,1,1,1,1,1,1,1,1
endlayer

layer
8,8,8,8,8,8,8,8,8,8,8,8,8,8,8
8,8,8,8,8,8,8,8,8,8,8,8,8,8,8
8,8,8,8,8,8,8,2,2,2,2,8,8,8,8
8,8,8,8,8,8,2,4,0,0,0,2,8,8,8
8,8,8,8,8,8,2,7,0,0,0,0,2,8,8
8,8,8,8,8,8,2,0,0,0,4,2,8,8,8
8,8,8,8,8,8,8,2,2,2,2,8,8,8,8
8,8,8,8,8,8,8,8,8,8,8,8,8,8,8
8,8,8,8,8,8,8,8,8,8,8,8,8,8,8
endlayer

layer
8,8,8,8,8,8,8,8,8,8,8,8,8,8,8
8,8,8,8,8,8,8,8,8,8,8,8,8,8,8
8,8,8,8,9,9,9,9,9,9,9,8,8,8,8
8,8,3,9,9,9,9,9,9,9,9,9,8,8,8
8,8,3,9,9,9,9,7,0,9,9,9,8,8,8
8,8,3,9,9,9,9,9,9,9,9,9,8,8,8
8,8,8,8,9,9,9,9,9,9,9,8,8,8,8
8,8,8,8,8,8,8,8,8,8,8,8,8,8,8
8,8,8,8,8,8,8,8,8,8,8,8,8,8,8
endlayer

layer
0,0,0,0,10,0,0,0,0,0,0,0,10,0,0
12,0,0,10,11,11,11,11,11,11,11,11,11,10,0
0,15,14,11,0,0,0,13,0,0,0,10,11,0,0
0,0,15,0,0,16,0,0,0,0,0,0,11,0,0
0,0,0,0,0,0,0,18,17,0,6,0,11,0,0
0,0,15,0,0,0,0,16,0,0,0,0,11,0,0
0,15,14,11,0,13,0,0,0,0,0,10,11,0,0
12,0,0,10,11,11,11,11,11,11,11,11,11,10,0
0,0,0,0,10,0,0,0,0,0,0,0,10,0,0
endlayer

layer
0,0,0,0,10,0,0,0,0,0,0,0,10,0,0
20,0,0,10,19,19,19,19,19,19,19,19,19,10,0
0,15,14,19,0,0,0,0,0,0,0,10,19,0,0
0,0,15,0,0,0,0,0,0,0,0,0,19,0,0
0,0,0,0,0,0,0,0,0,0,0,0,19,0,0
0,0,15,0,0,0,0,0,0,0,0,0,19,0,0
0,15,14,19,0,0,0,0,0,0,0,10,19,0,0
20,0,0,10,19,19,19,19,19,19,19,19,19,10,0
0,0,0,0,10,0,0,0,0,0,0,0,10,0,0
endlayer

layer
0,0,0,0,10,0,0,0,0,0,0,0,10,0,0
0,0,0,10,19,19,19,19,19,19,19,19,19,10,0
0,15,14,19,4,0,0,0,0,0,0,10,19,0,0
0,0,15,0,0,0,0,0,0,0,0,0,19,0,0
0,0,15,0,0,0,0,0,0,0,0,0,19,0,0
0,0,15,0,0,0,0,0,0,0,0,0,19,0,0
0,15,14,19,0,0,0,0,0,0,0,10,19,0,0
0,0,0,10,19,19,19,19,19,19,19,19,19,10,0
0,0,0,0,10,0,0,0,0,0,0,0,10,0,0
endlayer

layer
0,0,0,0,10,0,0,0,0,0,0,0,10,0,0
0,0,0,10,19,19,19,19,19,19,19,19,19,10,0
0,15,10,19,0,4,0,0,0,0,0,10,19,0,0
0,0,14,0,0,0,0,0,0,0,0,0,19,0,0
0,0,14,0,0,0,0,0,0,0,0,0,19,0,0
0,0,14,0,0,0,0,0,0,0,0,4,19,0,0
0,15,10,19,0,0,0,0,0,0,0,10,19,0,0
0,0,0,10,19,19,19,19,19,19,19,19,19,10,0
0,0,0,0,10,0,0,0,0,0,0,0,10,0,0
endlayer

layer
0,21,21,21,21,21,21,21,21,21,21,21,21,21,21
0,22,22,23,22,22,22,22,22,22,22,22,22,23,22
0,15,10,10,3,3,3,3,3,3,3,0,10,0,0
0,0,10,3,3,3,3,3,3,3,3,3,10,0,0
0,0,10,3,3,3,3,3,3,3,3,3,10,0,0
0,0,10,3,3,3,3,3,3,3,3,3,10,0,0
0,15,10,10,3,3,3,3,3,3,3,0,10,0,0
0,22,22,23,22,22,22,22,22,22,22,22,22,23,22
0,21,21,21,21,21,21,21,21,21,21,21,21,21,21
endlayer

layer
0,0,0,0,0,0,0,0,0,0,0,0,0,0,0
0,0,0,0,0,0,0,0,0,0,0,0,0,0,0
0,21,21,21,21,21,21,21,21,21,21,21,21,21,21
0,22,23,22,22,22,22,22,22,22,22,22,23,22,22
0,0,10,0,0,0,0,0,0,0,0,0,10,0,0
0,22,23,22,22,22,22,22,22,22,22,22,23,22,22
0,21,21,21,21,21,21,21,21,21,21,21,21,21,21
0,0,0,0,0,0,0,0,0,0,0,0,0,0,0
0,0,0,0,0,0,0,0,0,0,0,0,0,0,0
endlayer

layer
0,0,0,0,0,0,0,0,0,0,0,0,0,0,0
0,0,0,0,0,0,0,0,0,0,0,0,0,0,0
0,0,0,0,0,0,0,0,0,0,0,0,0,0,0
0,0,0,0,0,0,0,0,0,0,0,0,0,0,0
0,21,21,21,21,21,21,21,21,21,21,21,21,21,21
0,0,0,0,0,0,0,0,0,0,0,0,0,0,0
0,0,0,0,0,0,0,0,0,0,0,0,0,0,0
0,0,0,0,0,0,0,0,0,0,0,0,0,0,0
0,0,0,0,0,0,0,0,0,0,0,0,0,0,0
endlayer

