
# Created by Ruins mod version 14.5 Ingame Parser
# authoring Player: thephoenixlodge

weight=20
embed_into_distance=0
acceptable_target_blocks=ExtrabiomesXL:terrain_blocks2,grass
unacceptable_target_blocks=flowing_water,water,flowing_lava,lava
dimensions=10,5,8
allowable_overhang=0
max_leveling=2
leveling_buffer=0
preserve_water=0
preserve_lava=0

rule1=0,100,preserveBlock
rule2=0,100,Quadrum:deadWood-4
rule3=0,100,Quadrum:deadWood-0
rule4=0,100,Quadrum:charredWood-3
rule5=0,100,Quadrum:charredWood-5
rule6=0,100,Quadrum:charredWood-2

layer
1,1,1,1,1,1,1,1
1,1,1,1,1,1,1,1
1,1,1,1,1,1,1,1
1,1,1,2,1,1,1,1
1,1,1,1,1,1,1,1
endlayer

layer
1,1,1,1,1,1,1,1
1,1,1,1,1,1,1,1
1,1,1,1,1,1,1,1
1,1,1,3,1,1,1,1
1,1,1,1,1,1,1,1
endlayer

layer
1,1,1,1,1,1,1,1
1,1,1,1,1,1,1,1
1,1,1,1,1,1,1,1
1,1,1,3,1,1,1,1
1,1,1,1,1,1,1,1
endlayer

layer
1,1,1,1,1,1,1,1
1,1,1,1,1,1,1,1
1,1,1,1,1,1,1,1
1,1,1,3,1,1,1,1
1,1,1,1,1,1,1,1
endlayer

layer
0,0,0,0,0,0,0,0
0,0,3,0,0,0,0,0
0,0,4,0,0,0,0,0
0,0,0,3,0,0,0,0
0,0,0,0,0,0,0,0
endlayer

layer
0,3,0,0,0,0,0,0
0,0,0,0,0,0,0,0
0,0,0,3,0,0,0,0
0,0,0,3,0,0,0,0
0,0,0,0,0,0,0,0
endlayer

layer
0,0,0,0,0,0,0,0
0,0,0,0,0,3,0,0
0,3,0,0,3,0,0,0
0,0,3,3,0,0,0,0
0,0,0,0,0,0,0,0
endlayer

layer
0,0,0,0,0,0,3,0
0,0,0,0,0,0,0,0
0,3,3,0,0,0,0,0
0,0,0,3,3,3,0,0
0,0,0,0,5,0,0,0
endlayer

layer
0,0,0,0,0,0,0,0
3,0,0,0,0,0,0,0
0,0,0,0,0,0,3,6
0,0,0,3,0,0,0,0
0,0,0,0,0,0,0,0
endlayer

layer
0,0,0,0,0,0,0,0
0,0,0,0,0,0,0,0
0,0,0,0,0,0,0,0
0,0,0,6,0,0,0,0
0,0,0,0,0,0,0,0
endlayer

